"""
Подвиг 2. Вы видите в консольном окне следующие строчки сообщения об ошибке:

Traceback (most recent call last):
  File "D:\Python\Projects\oop\ex1.py", line 26, in <module>
    el = Ellipse(1, 2, 3, 4, '1')
  File "D:\Python\Projects\oop\ex1.py", line 12, in __init__
    super().__init__(width, color)
  File "D:\Python\Projects\oop\ex1.py", line 4, in __init__
    raise ValueError('неверные параметры фигуры')
ValueError: неверные параметры фигуры

Выберите все верные утверждения, которые можно сделать из этого вывода.

исключение ValueError сгенерировано в 26-й строчке программы и связано с работой команд, записанных в 12-й и 4-й строчках
    исключение ValueError сгенерировано в 4-й строчке программы в методе __init__()
    исключение ValueError сгенерировано в 4-й строчке программы и связано с работой команд, записанных в 12-й и 26-й строчках
    исключение ValueError не было обработано в основном модуле программы в 26-й строчке
    исключение ValueError стало следствием вызова метода __init__() в 12-й строчке программы
"""
