# Подвиг 3. Имеется следующий фрагмент программы:

try:
    val = float(input())
except ValueError as e:
    print(e)
else:
    val *= 10
    print(val, 'отработал ELSE')
finally:
    print("отработал finally")

# При каких входных данных выполнение программы перейдет в блок finally?

# при вводе любых целочисленных значений
# при вводе любых строк (данных)
# при вводе любых вещественных значений
# программа не будет выполнена, так как блок finally должен быть записан перед блоком else
# всегда будет переходить, вне зависимости от возникновения исключений
